Workbook

Sheet 📋 Product Manager
A1: SUNFORD VALVES COMPANY — PRODUCT MANAGER (Single Source of Truth)
A2: Edit this table only. All type sheets and the price summary auto-refresh from here. Do NOT edit type sheets directly.
A3: 🟢 ADD NEW PRODUCT | C3: Scroll to the bottom of the table → type a new row. Fill Valve_Type, Valve_Name, MOC, Size, Rate, Status. The type sheet will auto-include it IF Valve_Type matches exactly.
A4: ✏️ EDIT PRICE / FIELD | C4: Click the cell directly. Change the value. Save (Ctrl+S). All linked sheets will recalculate on next open.
A5: 🔴 HIDE A PRODUCT | C5: Set Status column = Inactive. The product stays in data but is marked for the website to filter out.
A6: 🗑️ DELETE A PRODUCT | C6: Select the entire row → Right-click → Delete Row. All type sheet formulas will auto-adjust (they use row-specific references).
A7: Valve_Type | B7: Valve_Name | C7: Description | D7: MOC | E7: Size | F7: Pressure_Class | G7: End_Connection | H7: Design_Standard | I7: Hydro_Test | J7: Unit | K7: Rate_INR | L7: Status | M7: Last_Updated | N7: Remarks
A8: Gate Valves | B8: Cast Carbon Steel (ASTM A216 Gr. WCB) Outside Screw & Yoke Type Bolted Bonnet Non Rotating Rising Spindle Gate Valve, Flanged End, Hand Wheel Operated ASA 150# | C8: Design: API 600 | Body: ASTM A216 Gr WCB | Trims: 13% Cr SS410 (Trim-1) | F-F: ASME B16.10 | Pressure: ASME B16.34 | Test: API 598 | Hydro: Body 32, Seat 23 Kg/Cm2 | D8: ASTM A216 Gr WCB + 13% Cr SS410 | E8: 1" | H8: API 600 | I8: Body 32, Seat 23 Kg/Cm2 | J8: Nos | K8: 5755 | L8: Active
A9: Gate Valves | B9: Cast Carbon Steel (ASTM A216 Gr. WCB) Outside Screw & Yoke Type Bolted Bonnet Non Rotating Rising Spindle Gate Valve, Flanged End, Hand Wheel Operated ASA 150# | C9: Design: API 600 | Body: ASTM A216 Gr WCB | Trims: 13% Cr SS410 (Trim-1) | F-F: ASME B16.10 | Pressure: ASME B16.34 | Test: API 598 | Hydro: Body 32, Seat 23 Kg/Cm2 | D9: ASTM A216 Gr WCB + 13% Cr SS410 | E9: 1.5" | H9: API 600 | I9: Body 32, Seat 23 Kg/Cm2 | J9: Nos | K9: 8855 | L9: Active
A10: Gate Valves | B10: Cast Carbon Steel (ASTM A216 Gr. WCB) Outside Screw & Yoke Type Bolted Bonnet Non Rotating Rising Spindle Gate Valve, Flanged End, Hand Wheel Operated ASA 150# | C10: Design: API 600 | Body: ASTM A216 Gr WCB | Trims: 13% Cr SS410 (Trim-1) | F-F: ASME B16.10 | Pressure: ASME B16.34 | Test: API 598 | Hydro: Body 32, Seat 23 Kg/Cm2 | D10: ASTM A216 Gr WCB + 13% Cr SS410 | E10: 2" | H10: API 600 | I10: Body 32, Seat 23 Kg/Cm2 | J10: Nos | K10: 11355 | L10: Active
A11: Gate Valves | B11: Cast Carbon Steel (ASTM A216 Gr. WCB) Outside Screw & Yoke Type Bolted Bonnet Non Rotating Rising Spindle Gate Valve, Flanged End, Hand Wheel Operated ASA 150# | C11: Design: API 600 | Body: ASTM A216 Gr WCB | Trims: 13% Cr SS410 (Trim-1) | F-F: ASME B16.10 | Pressure: ASME B16.34 | Test: API 598 | Hydro: Body 32, Seat 23 Kg/Cm2 | D11: ASTM A216 Gr WCB + 13% Cr SS410 | E11: 2.5" | H11: API 600 | I11: Body 32, Seat 23 Kg/Cm2 | J11: Nos | K11: 15555 | L11: Active
A12: Gate Valves | B12: Cast Carbon Steel (ASTM A216 Gr. WCB) Outside Screw & Yoke Type Bolted Bonnet Non Rotating Rising Spindle Gate Valve, Flanged End, Hand Wheel Operated ASA 150# | C12: Design: API 600 | Body: ASTM A216 Gr WCB | Trims: 13% Cr SS410 (Trim-1) | F-F: ASME B16.10 | Pressure: ASME B16.34 | Test: API 598 | Hydro: Body 32, Seat 23 Kg/Cm2 | D12: ASTM A216 Gr WCB + 13% Cr SS410 | E12: 3" | H12: API 600 | I12: Body 32, Seat 23 Kg/Cm2 | J12: Nos | K12: 18555 | L12: Active
A13: Gate Valves | B13: Cast Carbon Steel (ASTM A216 Gr. WCB) Outside Screw & Yoke Type Bolted Bonnet Non Rotating Rising Spindle Gate Valve, Flanged End, Hand Wheel Operated ASA 150# | C13: Design: API 600 | Body: ASTM A216 Gr WCB | Trims: 13% Cr SS410 (Trim-1) | F-F: ASME B16.10 | Pressure: ASME B16.34 | Test: API 598 | Hydro: Body 32, Seat 23 Kg/Cm2 | D13: ASTM A216 Gr WCB + 13% Cr SS410 | E13: 4" | H13: API 600 | I13: Body 32, Seat 23 Kg/Cm2 | J13: Nos | K13: 26555 | L13: Active
A14: Gate Valves | B14: Cast Carbon Steel (ASTM A216 Gr. WCB) Outside Screw & Yoke Type Bolted Bonnet Non Rotating Rising Spindle Gate Valve, Flanged End, Hand Wheel Operated ASA 150# | C14: Design: API 600 | Body: ASTM A216 Gr WCB | Trims: 13% Cr SS410 (Trim-1) | F-F: ASME B16.10 | Pressure: ASME B16.34 | Test: API 598 | Hydro: Body 32, Seat 23 Kg/Cm2 | D14: ASTM A216 Gr WCB + 13% Cr SS410 | E14: 5" | H14: API 600 | I14: Body 32, Seat 23 Kg/Cm2 | J14: Nos | K14: 34555 | L14: Active
A15: Gate Valves | B15: Cast Carbon Steel (ASTM A216 Gr. WCB) Outside Screw & Yoke Type Bolted Bonnet Non Rotating Rising Spindle Gate Valve, Flanged End, Hand Wheel Operated ASA 150# | C15: Design: API 600 | Body: ASTM A216 Gr WCB | Trims: 13% Cr SS410 (Trim-1) | F-F: ASME B16.10 | Pressure: ASME B16.34 | Test: API 598 | Hydro: Body 32, Seat 23 Kg/Cm2 | D15: ASTM A216 Gr WCB + 13% Cr SS410 | E15: 6" | H15: API 600 | I15: Body 32, Seat 23 Kg/Cm2 | J15: Nos | K15: 40955 | L15: Active
A16: Gate Valves | B16: Cast Carbon Steel (ASTM A216 Gr. WCB) Outside Screw & Yoke Type Bolted Bonnet Non Rotating Rising Spindle Gate Valve, Flanged End, Hand Wheel Operated ASA 150# | C16: Design: API 600 | Body: ASTM A216 Gr WCB | Trims: 13% Cr SS410 (Trim-1) | F-F: ASME B16.10 | Pressure: ASME B16.34 | Test: API 598 | Hydro: Body 32, Seat 23 Kg/Cm2 | D16: ASTM A216 Gr WCB + 13% Cr SS410 | E16: 8" | H16: API 600 | I16: Body 32, Seat 23 Kg/Cm2 | J16: Nos | K16: 65555 | L16: Active
A17: Gate Valves | B17: Cast Carbon Steel (ASTM A216 Gr. WCB) Outside Screw & Yoke Type Bolted Bonnet Non Rotating Rising Spindle Gate Valve, Flanged End, Hand Wheel Operated ASA 150# | C17: Design: API 600 | Body: ASTM A216 Gr WCB | Trims: 13% Cr SS410 (Trim-1) | F-F: ASME B16.10 | Pressure: ASME B16.34 | Test: API 598 | Hydro: Body 32, Seat 23 Kg/Cm2 | D17: ASTM A216 Gr WCB + 13% Cr SS410 | E17: 10" | H17: API 600 | I17: Body 32, Seat 23 Kg/Cm2 | J17: Nos | K17: 91155 | L17: Active
A18: Gate Valves | B18: Cast Carbon Steel (ASTM A216 Gr. WCB) Outside Screw & Yoke Type Bolted Bonnet Non Rotating Rising Spindle Gate Valve, Flanged End, Hand Wheel Operated ASA 150# | C18: Design: API 600 | Body: ASTM A216 Gr WCB | Trims: 13% Cr SS410 (Trim-1) | F-F: ASME B16.10 | Pressure: ASME B16.34 | Test: API 598 | Hydro: Body 32, Seat 23 Kg/Cm2 | D18: ASTM A216 Gr WCB + 13% Cr SS410 | E18: 12" | H18: API 600 | I18: Body 32, Seat 23 Kg/Cm2 | J18: Nos | K18: On Request | L18: Active
A19: Globe Valves | B19: Cast Carbon Steel (ASTM A216 Gr. WCB) Outside Screw & Yoke Type Bolted Bonnet Globe Valve, Flanged End, Handwheel Operated ASA 150# | C19: Design: BS 1873 / API 6D | Body: ASTM A216 Gr WCB | Trims: 13% Cr SS410 (Trim-1) | F-F: ASME B16.10 | Pressure: ASME B16.34 | Test: API 598 | Hydro: Body 32, Seat 23 Kg/Cm2 | D19: ASTM A216 Gr WCB + 13% Cr SS410 | E19: 1" | H19: BS 1873 / API 6D | I19: Body 32, Seat 23 Kg/Cm2 | J19: Nos | K19: 5555 | L19: Active
A20: Globe Valves | B20: Cast Carbon Steel (ASTM A216 Gr. WCB) Outside Screw & Yoke Type Bolted Bonnet Globe Valve, Flanged End, Handwheel Operated ASA 150# | C20: Design: BS 1873 / API 6D | Body: ASTM A216 Gr WCB | Trims: 13% Cr SS410 (Trim-1) | F-F: ASME B16.10 | Pressure: ASME B16.34 | Test: API 598 | Hydro: Body 32, Seat 23 Kg/Cm2 | D20: ASTM A216 Gr WCB + 13% Cr SS410 | E20: 1.5" | H20: BS 1873 / API 6D | I20: Body 32, Seat 23 Kg/Cm2 | J20: Nos | K20: 7655 | L20: Active
A21: Globe Valves | B21: Cast Carbon Steel (ASTM A216 Gr. WCB) Outside Screw & Yoke Type Bolted Bonnet Globe Valve, Flanged End, Handwheel Operated ASA 150# | C21: Design: BS 1873 / API 6D | Body: ASTM A216 Gr WCB | Trims: 13% Cr SS410 (Trim-1) | F-F: ASME B16.10 | Pressure: ASME B16.34 | Test: API 598 | Hydro: Body 32, Seat 23 Kg/Cm2 | D21: ASTM A216 Gr WCB + 13% Cr SS410 | E21: 2" | H21: BS 1873 / API 6D | I21: Body 32, Seat 23 Kg/Cm2 | J21: Nos | K21: 11355 | L21: Active
A22: Globe Valves | B22: Cast Carbon Steel (ASTM A216 Gr. WCB) Outside Screw & Yoke Type Bolted Bonnet Globe Valve, Flanged End, Handwheel Operated ASA 150# | C22: Design: BS 1873 / API 6D | Body: ASTM A216 Gr WCB | Trims: 13% Cr SS410 (Trim-1) | F-F: ASME B16.10 | Pressure: ASME B16.34 | Test: API 598 | Hydro: Body 32, Seat 23 Kg/Cm2 | D22: ASTM A216 Gr WCB + 13% Cr SS410 | E22: 2.5" | H22: BS 1873 / API 6D | I22: Body 32, Seat 23 Kg/Cm2 | J22: Nos | K22: 15355 | L22: Active
A23: Globe Valves | B23: Cast Carbon Steel (ASTM A216 Gr. WCB) Outside Screw & Yoke Type Bolted Bonnet Globe Valve, Flanged End, Handwheel Operated ASA 150# | C23: Design: BS 1873 / API 6D | Body: ASTM A216 Gr WCB | Trims: 13% Cr SS410 (Trim-1) | F-F: ASME B16.10 | Pressure: ASME B16.34 | Test: API 598 | Hydro: Body 32, Seat 23 Kg/Cm2 | D23: ASTM A216 Gr WCB + 13% Cr SS410 | E23: 3" | H23: BS 1873 / API 6D | I23: Body 32, Seat 23 Kg/Cm2 | J23: Nos | K23: 18155 | L23: Active
A24: Globe Valves | B24: Cast Carbon Steel (ASTM A216 Gr. WCB) Outside Screw & Yoke Type Bolted Bonnet Globe Valve, Flanged End, Handwheel Operated ASA 150# | C24: Design: BS 1873 / API 6D | Body: ASTM A216 Gr WCB | Trims: 13% Cr SS410 (Trim-1) | F-F: ASME B16.10 | Pressure: ASME B16.34 | Test: API 598 | Hydro: Body 32, Seat 23 Kg/Cm2 | D24: ASTM A216 Gr WCB + 13% Cr SS410 | E24: 4" | H24: BS 1873 / API 6D | I24: Body 32, Seat 23 Kg/Cm2 | J24: Nos | K24: 26955 | L24: Active
A25: Globe Valves | B25: Cast Carbon Steel (ASTM A216 Gr. WCB) Outside Screw & Yoke Type Bolted Bonnet Globe Valve, Flanged End, Handwheel Operated ASA 150# | C25: Design: BS 1873 / API 6D | Body: ASTM A216 Gr WCB | Trims: 13% Cr SS410 (Trim-1) | F-F: ASME B16.10 | Pressure: ASME B16.34 | Test: API 598 | Hydro: Body 32, Seat 23 Kg/Cm2 | D25: ASTM A216 Gr WCB + 13% Cr SS410 | E25: 5" | H25: BS 1873 / API 6D | I25: Body 32, Seat 23 Kg/Cm2 | J25: Nos | K25: 34655 | L25: Active
A26: Globe Valves | B26: Cast Carbon Steel (ASTM A216 Gr. WCB) Outside Screw & Yoke Type Bolted Bonnet Globe Valve, Flanged End, Handwheel Operated ASA 150# | C26: Design: BS 1873 / API 6D | Body: ASTM A216 Gr WCB | Trims: 13% Cr SS410 (Trim-1) | F-F: ASME B16.10 | Pressure: ASME B16.34 | Test: API 598 | Hydro: Body 32, Seat 23 Kg/Cm2 | D26: ASTM A216 Gr WCB + 13% Cr SS410 | E26: 6" | H26: BS 1873 / API 6D | I26: Body 32, Seat 23 Kg/Cm2 | J26: Nos | K26: 41155 | L26: Active
A27: Globe Valves | B27: Cast Carbon Steel (ASTM A216 Gr. WCB) Outside Screw & Yoke Type Bolted Bonnet Globe Valve, Flanged End, Handwheel Operated ASA 150# | C27: Design: BS 1873 / API 6D | Body: ASTM A216 Gr WCB | Trims: 13% Cr SS410 (Trim-1) | F-F: ASME B16.10 | Pressure: ASME B16.34 | Test: API 598 | Hydro: Body 32, Seat 23 Kg/Cm2 | D27: ASTM A216 Gr WCB + 13% Cr SS410 | E27: 8" | H27: BS 1873 / API 6D | I27: Body 32, Seat 23 Kg/Cm2 | J27: Nos | K27: 67955 | L27: Active
A28: Globe Valves | B28: Cast Carbon Steel (ASTM A216 Gr. WCB) Outside Screw & Yoke Type Bolted Bonnet Globe Valve, Flanged End, Handwheel Operated ASA 150# | C28: Design: BS 1873 / API 6D | Body: ASTM A216 Gr WCB | Trims: 13% Cr SS410 (Trim-1) | F-F: ASME B16.10 | Pressure: ASME B16.34 | Test: API 598 | Hydro: Body 32, Seat 23 Kg/Cm2 | D28: ASTM A216 Gr WCB + 13% Cr SS410 | E28: 10" / 12" Gear Opp | H28: BS 1873 / API 6D | I28: Body 32, Seat 23 Kg/Cm2 | J28: Nos | K28: 115655 | L28: Active
A29: Control Valves | B29: Cast Carbon Steel (ASTM A216 Gr. WCB) Investment Casting 3/2 Way Globe Type Pneumatic Cylinder Operated Control Valve, F/Ends ASA 150# | C29: Design: MFG STD | Body: ASTM A216 Gr WCB | Trims: S.S.304 (Trim-2) | F-F: MFG STD | Pressure: ASME B16.34 | Test: API 598 | Hydro: Body 32, Seat 23 Kg/Cm2 | D29: WCB Body + SS304 Trim, Pneumatic Cylinder | E29: 1" | H29: MFG STD | I29: Body 32, Seat 23 Kg/Cm2 | J29: Nos | K29: 14655 | L29: Active
A30: Control Valves | B30: Cast Carbon Steel (ASTM A216 Gr. WCB) Investment Casting 3/2 Way Globe Type Pneumatic Cylinder Operated Control Valve, F/Ends ASA 150# | C30: Design: MFG STD | Body: ASTM A216 Gr WCB | Trims: S.S.304 (Trim-2) | F-F: MFG STD | Pressure: ASME B16.34 | Test: API 598 | Hydro: Body 32, Seat 23 Kg/Cm2 | D30: WCB Body + SS304 Trim, Pneumatic Cylinder | E30: 1.5" | H30: MFG STD | I30: Body 32, Seat 23 Kg/Cm2 | J30: Nos | K30: 21955 | L30: Active
... A61: Check Valves | B61: Cast Carbon Steel (ASTM A216 Gr. WCB) Swing Type Non Return Valve with Bolted Cover, Flanged Ends ASA 150# | C61: Design: BS 1868 / API 602 | Body: ASTM A216 Gr WCB | Trims: 13% Cr SS410 (Trim-1) | F-F: ASME B16.10 | Pressure: ASME B16.34 | Test: API 598 | Hydro: Body 32, Seat 23 Kg/Cm2 | D61: ASTM A216 Gr WCB + 13% Cr SS410 | E61: 10" | H61: BS 1868 / API 602 | I61: Body 32, Seat 23 Kg/Cm2 | J61: Nos | K61: 96555 | L61: Active
A62: Safety Valves | B62: Cast Carbon Steel (ASTM A216 Gr. WCB) Globe Type Safety Valve, Flanged End ASA 150# | C62: Design: BS 1873 | Body: ASTM A216 Gr WCB | Trims: 13% Cr SS410 (Trim-1) | F-F: ASME B16.10 | Pressure: ASME B16.34 | Test: API 598 | Hydro: Body 32, Seat 23 Kg/Cm2 | D62: ASTM A105 + 13% Cr (Trim-1) | E62: 1" | H62: BS 1873 | I62: Body 32, Seat 23 Kg/Cm2 | J62: Nos | K62: On Request | L62: Active
A63: Safety Valves | B63: Cast Carbon Steel (ASTM A216 Gr. WCB) Globe Type Safety Valve, Flanged End ASA 150# | C63: Design: BS 1873 | Body: ASTM A216 Gr WCB | Trims: 13% Cr SS410 (Trim-1) | F-F: ASME B16.10 | Pressure: ASME B16.34 | Test: API 598 | Hydro: Body 32, Seat 23 Kg/Cm2 | D63: ASTM A105 + 13% Cr (Trim-1) | E63: 1.5" | H63: BS 1873 | I63: Body 32, Seat 23 Kg/Cm2 | J63: Nos | K63: 13155 | L63: Active
A64: Safety Valves | B64: Cast Carbon Steel (ASTM A216 Gr. WCB) Globe Type Safety Valve, Flanged End ASA 150# | C64: Design: BS 1873 | Body: ASTM A216 Gr WCB | Trims: 13% Cr SS410 (Trim-1) | F-F: ASME B16.10 | Pressure: ASME B16.34 | Test: API 598 | Hydro: Body 32, Seat 23 Kg/Cm2 | D64: ASTM A105 + 13% Cr (Trim-1) | E64: 2" | H64: BS 1873 | I64: Body 32, Seat 23 Kg/Cm2 | J64: Nos | K64: 15155 | L64: Active
A65: Safety Valves | B65: Cast Carbon Steel (ASTM A216 Gr. WCB) Globe Type Safety Valve, Flanged End ASA 150# | C65: Design: BS 1873 | Body: ASTM A216 Gr WCB | Trims: 13% Cr SS410 (Trim-1) | F-F: ASME B16.10 | Pressure: ASME B16.34 | Test: API 598 | Hydro: Body 32, Seat 23 Kg/Cm2 | D65: ASTM A105 + 13% Cr (Trim-1) | E65: 3" | H65: BS 1873 | I65: Body 32, Seat 23 Kg/Cm2 | J65: Nos | K65: 25155 | L65: Active
A66: Safety Valves | B66: Cast Carbon Steel (ASTM A216 Gr. WCB) Globe Type Safety Valve, Flanged End ASA 150# | C66: Design: BS 1873 | Body: ASTM A216 Gr WCB | Trims: 13% Cr SS410 (Trim-1) | F-F: ASME B16.10 | Pressure: ASME B16.34 | Test: API 598 | Hydro: Body 32, Seat 23 Kg/Cm2 | D66: ASTM A105 + 13% Cr (Trim-1) | E66: 4" | H66: BS 1873 | I66: Body 32, Seat 23 Kg/Cm2 | J66: Nos | K66: 33755 | L66: Active
A67: Ball Valves | B67: 2PC/3PC Design with Blow Out Proof Stem Full Bore Handle Operated Investment Casting Ball Valve, F/Ends ASA 150# | C67: Design: BS 5351 / API 6D | Body: ASTM A216 Gr WCB/ CF8/ CF8M/ CF3/ CF3M | Trims: S.S.304/ S.S.316/ S.S.304L/ S.S.316L | F-F: ASME B16.10 | Pressure: ASME B16.34 | Test: API 598 | Hydro: Body 32, Seat 23 Kg/Cm2 | D67: CF8M (S.S.316) + CF8M (S.S.316) | E67: 1/2" | H67: BS 5351 / API 6D | I67: Body 32, Seat 23 Kg/Cm2 | J67: Nos | K67: 2895 | L67: Active
A68: Ball Valves | B68: 2PC/3PC Design with Blow Out Proof Stem Full Bore Handle Operated Investment Casting Ball Valve, F/Ends ASA 150# | C68: Design: BS 5351 / API 6D | Body: ASTM A216 Gr WCB/ CF8/ CF8M/ CF3/ CF3M | Trims: S.S.304/ S.S.316/ S.S.304L/ S.S.316L | F-F: ASME B16.10 | Pressure: ASME B16.34 | Test: API 598 | Hydro: Body 32, Seat 23 Kg/Cm2 | D68: CF8M (S.S.316) + CF8M (S.S.316) | E68: 3/4" | H68: BS 5351 / API 6D | I68: Body 32, Seat 23 Kg/Cm2 | J68: Nos | K68: 3395 | L68: Active
A69: Ball Valves | B69: 2PC/3PC Design with Blow Out Proof Stem Full Bore Handle Operated Investment Casting Ball Valve, F/Ends ASA 150# | C69: Design: BS 5351 / API 6D | Body: ASTM A216 Gr WCB/ CF8/ CF8M/ CF3/ CF3M | Trims: S.S.304/ S.S.316/ S.S.304L/ S.S.316L | F-F: ASME B16.10 | Pressure: ASME B16.34 | Test: API 598 | Hydro: Body 32, Seat 23 Kg/Cm2 | D69: CF8M (S.S.316) + CF8M (S.S.316) | E69: 1" | H69: BS 5351 / API 6D | I69: Body 32, Seat 23 Kg/Cm2 | J69: Nos | K69: 4555 | L69: Active
A70: Ball Valves | B70: 2PC/3PC Design with Blow Out Proof Stem Full Bore Handle Operated Investment Casting Ball Valve, F/Ends ASA 150# | C70: Design: BS 5351 / API 6D | Body: ASTM A216 Gr WCB/ CF8/ CF8M/ CF3/ CF3M | Trims: S.S.304/ S.S.316/ S.S.304L/ S.S.316L | F-F: ASME B16.10 | Pressure: ASME B16.34 | Test: API 598 | Hydro: Body 32, Seat 23 Kg/Cm2 | D70: CF8M (S.S.316) + CF8M (S.S.316) | E70: 1.5" | H70: BS 5351 / API 6D | I70: Body 32, Seat 23 Kg/Cm2 | J70: Nos | K70: 7815 | L70: Active
...

Sheet 📊 Price Summary
A1: SUNFORD VALVES — PRICE RANGE SUMMARY BY PRODUCT TYPE
A2: Live-linked from 📋 Product Manager. Refresh with Ctrl+Alt+F9 to force recalculate. All prices INR Ex-Works Surat.
A4: Valve Type | B4: Total SKUs | C4: Active SKUs | D4: Size Variants | E4: Min Price (₹) | F4: Max Price (₹) | G4: Avg Price (₹) | H4: "On Request" Items | I4: Price Band | J4: Sheet Link
A5: Gate Valves | B5: =COUNTIF('📋 Product Manager'!$A$8:$A$222,A5) | C5: =COUNTIFS('📋 Product Manager'!$A$8:$A$222,A5,'📋 Product Manager'!$L$8:$L$222,"Active") | D5: =SUMPRODUCT((('📋 Product Manager'!$A$8:$A$222=A5)*1)/COUNTIFS('📋 Product Manager'!$A$8:$A$222,'📋 Product Manager'!$A$8:$A$222,'📋 Product Manager'!$E$8:$E$222,'📋 Product Manager'!$E$8:$E$222),('📋 Product Manager'!$A$8:$A$222=A5)*1) | E5: =IFERROR(MINIFS('📋 Product Manager'!$K$8:$K$222,'📋 Product Manager'!$A$8:$A$222,A5,'📋 Product Manager'!$K$8:$K$222,">0"),"-") | F5: =IFERROR(MAXIFS('📋 Product Manager'!$K$8:$K$222,'📋 Product Manager'!$A$8:$A$222,A5,'📋 Product Manager'!$K$8:$K$222,">0"),"-") | G5: =IFERROR(AVERAGEIFS('📋 Product Manager'!$K$8:$K$222,'📋 Product Manager'!$A$8:$A$222,A5,'📋 Product Manager'!$K$8:$K$222,">0"),"-") | H5: =COUNTIFS('📋 Product Manager'!$A$8:$A$222,A5,'📋 Product Manager'!$K$8:$K$222,"On Request") | I5: =IF(ISNUMBER(G5),IF(G5<5000,"⭐ Budget",IF(G5<20000,"⭐⭐ Mid",IF(G5<60000,"⭐⭐⭐ Premium","⭐⭐⭐⭐ High-End"))),"Custom") | J5: Go to Gate Valves
A6: Globe Valves | B6: =COUNTIF('📋 Product Manager'!$A$8:$A$222,A6) | C6: =COUNTIFS('📋 Product Manager'!$A$8:$A$222,A6,'📋 Product Manager'!$L$8:$L$222,"Active") | D6: =SUMPRODUCT((('📋 Product Manager'!$A$8:$A$222=A6)*1)/COUNTIFS('📋 Product Manager'!$A$8:$A$222,'📋 Product Manager'!$A$8:$A$222,'📋 Product Manager'!$E$8:$E$222,'📋 Product Manager'!$E$8:$E$222),('📋 Product Manager'!$A$8:$A$222=A6)*1) | E6: =IFERROR(MINIFS('📋 Product Manager'!$K$8:$K$222,'📋 Product Manager'!$A$8:$A$222,A6,'📋 Product Manager'!$K$8:$K$222,">0"),"-") | F6: =IFERROR(MAXIFS('📋 Product Manager'!$K$8:$K$222,'📋 Product Manager'!$A$8:$A$222,A6,'📋 Product Manager'!$K$8:$K$222,">0"),"-") | G6: =IFERROR(AVERAGEIFS('📋 Product Manager'!$K$8:$K$222,'📋 Product Manager'!$A$8:$A$222,A6,'📋 Product Manager'!$K$8:$K$222,">0"),"-") | H6: =COUNTIFS('📋 Product Manager'!$A$8:$A$222,A6,'📋 Product Manager'!$K$8:$K$222,"On Request") | I6: =IF(ISNUMBER(G6),IF(G6<5000,"⭐ Budget",IF(G6<20000,"⭐⭐ Mid",IF(G6<60000,"⭐⭐⭐ Premium","⭐⭐⭐⭐ High-End"))),"Custom") | J6: Go to Globe Valves
A7: Control Valves | B7: =COUNTIF('📋 Product Manager'!$A$8:$A$222,A7) | C7: =COUNTIFS('📋 Product Manager'!$A$8:$A$222,A7,'📋 Product Manager'!$L$8:$L$222,"Active") | D7: =SUMPRODUCT((('📋 Product Manager'!$A$8:$A$222=A7)*1)/COUNTIFS('📋 Product Manager'!$A$8:$A$222,'📋 Product Manager'!$A$8:$A$222,'📋 Product Manager'!$E$8:$E$222,'📋 Product Manager'!$E$8:$E$222),('📋 Product Manager'!$A$8:$A$222=A7)*1) | E7: =IFERROR(MINIFS('📋 Product Manager'!$K$8:$K$222,'📋 Product Manager'!$A$8:$A$222,A7,'📋 Product Manager'!$K$8:$K$222,">0"),"-") | F7: =IFERROR(MAXIFS('📋 Product Manager'!$K$8:$K$222,'📋 Product Manager'!$A$8:$A$222,A7,'📋 Product Manager'!$K$8:$K$222,">0"),"-") | G7: =IFERROR(AVERAGEIFS('📋 Product Manager'!$K$8:$K$222,'📋 Product Manager'!$A$8:$A$222,A7,'📋 Product Manager'!$K$8:$K$222,">0"),"-") | H7: =COUNTIFS('📋 Product Manager'!$A$8:$A$222,A7,'📋 Product Manager'!$K$8:$K$222,"On Request") | I7: =IF(ISNUMBER(G7),IF(G7<5000,"⭐ Budget",IF(G7<20000,"⭐⭐ Mid",IF(G7<60000,"⭐⭐⭐ Premium","⭐⭐⭐⭐ High-End"))),"Custom") | J7: Go to Control Valves
A8: Strainers | B8: =COUNTIF('📋 Product Manager'!$A$8:$A$222,A8) | C8: =COUNTIFS('📋 Product Manager'!$A$8:$A$222,A8,'📋 Product Manager'!$L$8:$L$222,"Active") | D8: =SUMPRODUCT((('📋 Product Manager'!$A$8:$A$222=A8)*1)/COUNTIFS('📋 Product Manager'!$A$8:$A$222,'📋 Product Manager'!$A$8:$A$222,'📋 Product Manager'!$E$8:$E$222,'📋 Product Manager'!$E$8:$E$222),('📋 Product Manager'!$A$8:$A$222=A8)*1) | E8: =IFERROR(MINIFS('📋 Product Manager'!$K$8:$K$222,'📋 Product Manager'!$A$8:$A$222,A8,'📋 Product Manager'!$K$8:$K$222,">0"),"-") | F8: =IFERROR(MAXIFS('📋 Product Manager'!$K$8:$K$222,'📋 Product Manager'!$A$8:$A$222,A8,'📋 Product Manager'!$K$8:$K$222,">0"),"-") | G8: =IFERROR(AVERAGEIFS('📋 Product Manager'!$K$8:$K$222,'📋 Product Manager'!$A$8:$A$222,A8,'📋 Product Manager'!$K$8:$K$222,">0"),"-") | H8: =COUNTIFS('📋 Product Manager'!$A$8:$A$222,A8,'📋 Product Manager'!$K$8:$K$222,"On Request") | I8: =IF(ISNUMBER(G8),IF(G8<5000,"⭐ Budget",IF(G8<20000,"⭐⭐ Mid",IF(G8<60000,"⭐⭐⭐ Premium","⭐⭐⭐⭐ High-End"))),"Custom") | J8: Go to Strainers
A9: Check Valves | B9: =COUNTIF('📋 Product Manager'!$A$8:$A$222,A9) | C9: =COUNTIFS('📋 Product Manager'!$A$8:$A$222,A9,'📋 Product Manager'!$L$8:$L$222,"Active") | D9: =SUMPRODUCT((('📋 Product Manager'!$A$8:$A$222=A9)*1)/COUNTIFS('📋 Product Manager'!$A$8:$A$222,'📋 Product Manager'!$A$8:$A$222,'📋 Product Manager'!$E$8:$E$222,'📋 Product Manager'!$E$8:$E$222),('📋 Product Manager'!$A$8:$A$222=A9)*1) | E9: =IFERROR(MINIFS('📋 Product Manager'!$K$8:$K$222,'📋 Product Manager'!$A$8:$A$222,A9,'📋 Product Manager'!$K$8:$K$222,">0"),"-") | F9: =IFERROR(MAXIFS('📋 Product Manager'!$K$8:$K$222,'📋 Product Manager'!$A$8:$A$222,A9,'📋 Product Manager'!$K$8:$K$222,">0"),"-") | G9: =IFERROR(AVERAGEIFS('📋 Product Manager'!$K$8:$K$222,'📋 Product Manager'!$A$8:$A$222,A9,'📋 Product Manager'!$K$8:$K$222,">0"),"-") | H9: =COUNTIFS('📋 Product Manager'!$A$8:$A$222,A9,'📋 Product Manager'!$K$8:$K$222,"On Request") | I9: =IF(ISNUMBER(G9),IF(G9<5000,"⭐ Budget",IF(G9<20000,"⭐⭐ Mid",IF(G9<60000,"⭐⭐⭐ Premium","⭐⭐⭐⭐ High-End"))),"Custom") | J9: Go to Check Valves
A10: Safety Valves | B10: =COUNTIF('📋 Product Manager'!$A$8:$A$222,A10) | C10: =COUNTIFS('📋 Product Manager'!$A$8:$A$222,A10,'📋 Product Manager'!$L$8:$L$222,"Active") | D10: =SUMPRODUCT((('📋 Product Manager'!$A$8:$A$222=A10)*1)/COUNTIFS('📋 Product Manager'!$A$8:$A$222,'📋 Product Manager'!$A$8:$A$222,'📋 Product Manager'!$E$8:$E$222,'📋 Product Manager'!$E$8:$E$222),('📋 Product Manager'!$A$8:$A$222=A10)*1) | E10: =IFERROR(MINIFS('📋 Product Manager'!$K$8:$K$222,'📋 Product Manager'!$A$8:$A$222,A10,'📋 Product Manager'!$K$8:$K$222,">0"),"-") | F10: =IFERROR(MAXIFS('📋 Product Manager'!$K$8:$K$222,'📋 Product Manager'!$A$8:$A$222,A10,'📋 Product Manager'!$K$8:$K$222,">0"),"-") | G10: =IFERROR(AVERAGEIFS('📋 Product Manager'!$K$8:$K$222,'📋 Product Manager'!$A$8:$A$222,A10,'📋 Product Manager'!$K$8:$K$222,">0"),"-") | H10: =COUNTIFS('📋 Product Manager'!$A$8:$A$222,A10,'📋 Product Manager'!$K$8:$K$222,"On Request") | I10: =IF(ISNUMBER(G10),IF(G10<5000,"⭐ Budget",IF(G10<20000,"⭐⭐ Mid",IF(G10<60000,"⭐⭐⭐ Premium","⭐⭐⭐⭐ High-End"))),"Custom") | J10: Go to Safety Valves
A11: Ball Valves | B11: =COUNTIF('📋 Product Manager'!$A$8:$A$222,A11) | C11: =COUNTIFS('📋 Product Manager'!$A$8:$A$222,A11,'📋 Product Manager'!$L$8:$L$222,"Active") | D11: =SUMPRODUCT((('📋 Product Manager'!$A$8:$A$222=A11)*1)/COUNTIFS('📋 Product Manager'!$A$8:$A$222,'📋 Product Manager'!$A$8:$A$222,'📋 Product Manager'!$E$8:$E$222,'📋 Product Manager'!$E$8:$E$222),('📋 Product Manager'!$A$8:$A$222=A11)*1) | E11: =IFERROR(MINIFS('📋 Product Manager'!$K$8:$K$222,'📋 Product Manager'!$A$8:$A$222,A11,'📋 Product Manager'!$K$8:$K$222,">0"),"-") | F11: =IFERROR(MAXIFS('📋 Product Manager'!$K$8:$K$222,'📋 Product Manager'!$A$8:$A$222,A11,'📋 Product Manager'!$K$8:$K$222,">0"),"-") | G11: =IFERROR(AVERAGEIFS('📋 Product Manager'!$K$8:$K$222,'📋 Product Manager'!$A$8:$A$222,A11,'📋 Product Manager'!$K$8:$K$222,">0"),"-") | H11: =COUNTIFS('📋 Product Manager'!$A$8:$A$222,A11,'📋 Product Manager'!$K$8:$K$222,"On Request") | I11: =IF(ISNUMBER(G11),IF(G11<5000,"⭐ Budget",IF(G11<20000,"⭐⭐ Mid",IF(G11<60000,"⭐⭐⭐ Premium","⭐⭐⭐⭐ High-End"))),"Custom") | J11: Go to Ball Valves
A12: Piston Valves | B12: =COUNTIF('📋 Product Manager'!$A$8:$A$222,A12) | C12: =COUNTIFS('📋 Product Manager'!$A$8:$A$222,A12,'📋 Product Manager'!$L$8:$L$222,"Active") | D12: =SUMPRODUCT((('📋 Product Manager'!$A$8:$A$222=A12)*1)/COUNTIFS('📋 Product Manager'!$A$8:$A$222,'📋 Product Manager'!$A$8:$A$222,'📋 Product Manager'!$E$8:$E$222,'📋 Product Manager'!$E$8:$E$222),('📋 Product Manager'!$A$8:$A$222=A12)*1) | E12: =IFERROR(MINIFS('📋 Product Manager'!$K$8:$K$222,'📋 Product Manager'!$A$8:$A$222,A12,'📋 Product Manager'!$K$8:$K$222,">0"),"-") | F12: =IFERROR(MAXIFS('📋 Product Manager'!$K$8:$K$222,'📋 Product Manager'!$A$8:$A$222,A12,'📋 Product Manager'!$K$8:$K$222,">0"),"-") | G12: =IFERROR(AVERAGEIFS('📋 Product Manager'!$K$8:$K$222,'📋 Product Manager'!$A$8:$A$222,A12,'📋 Product Manager'!$K$8:$K$222,">0"),"-") | H12: =COUNTIFS('📋 Product Manager'!$A$8:$A$222,A12,'📋 Product Manager'!$K$8:$K$222,"On Request") | I12: =IF(ISNUMBER(G12),IF(G12<5000,"⭐ Budget",IF(G12<20000,"⭐⭐ Mid",IF(G12<60000,"⭐⭐⭐ Premium","⭐⭐⭐⭐ High-End"))),"Custom") | J12: Go to Piston Valves
A13: Butterfly Valves | B13: =COUNTIF('📋 Product Manager'!$A$8:$A$222,A13) | C13: =COUNTIFS('📋 Product Manager'!$A$8:$A$222,A13,'📋 Product Manager'!$L$8:$L$222,"Active") | D13: =SUMPRODUCT((('📋 Product Manager'!$A$8:$A$222=A13)*1)/COUNTIFS('📋 Product Manager'!$A$8:$A$222,'📋 Product Manager'!$A$8:$A$222,'📋 Product Manager'!$E$8:$E$222,'📋 Product Manager'!$E$8:$E$222),('📋 Product Manager'!$A$8:$A$222=A13)*1) | E13: =IFERROR(MINIFS('📋 Product Manager'!$K$8:$K$222,'📋 Product Manager'!$A$8:$A$222,A13,'📋 Product Manager'!$K$8:$K$222,">0"),"-") | F13: =IFERROR(MAXIFS('📋 Product Manager'!$K$8:$K$222,'📋 Product Manager'!$A$8:$A$222,A13,'📋 Product Manager'!$K$8:$K$222,">0"),"-") | G13: =IFERROR(AVERAGEIFS('📋 Product Manager'!$K$8:$K$222,'📋 Product Manager'!$A$8:$A$222,A13,'📋 Product Manager'!$K$8:$K$222,">0"),"-") | H13: =COUNTIFS('📋 Product Manager'!$A$8:$A$222,A13,'📋 Product Manager'!$K$8:$K$222,"On Request") | I13: =IF(ISNUMBER(G13),IF(G13<5000,"⭐ Budget",IF(G13<20000,"⭐⭐ Mid",IF(G13<60000,"⭐⭐⭐ Premium","⭐⭐⭐⭐ High-End"))),"Custom") | J13: Go to Butterfly Valves
A14: PORTFOLIO TOTAL | E14: =MINIFS('📋 Product Manager'!$K$8:$K$222,'📋 Product Manager'!$K$8:$K$222,">0") | F14: =MAXIFS('📋 Product Manager'!$K$8:$K$222,'📋 Product Manager'!$K$8:$K$222,">0") | G14: =AVERAGEIFS('📋 Product Manager'!$K$8:$K$222,'📋 Product Manager'!$K$8:$K$222,">0") | H14: =COUNTIF('📋 Product Manager'!$K$8:$K$222,"On Request") | I14: =COUNTA('📋 Product Manager'!$A$8:$A$222) | J14: Go to Product Manager

Sheet ℹ️ How to Use
A1: SFVC PRODUCT WORKBOOK — USER GUIDE
A2: SHEET OVERVIEW
A3: 📋 Product Manager | B3: THE ONLY SHEET YOU SHOULD EDIT. All other sheets read from here via formulas. Changing a rate here = it instantly changes in the type sheet and price summary.
A4: 📊 Price Summary | B4: Auto-calculated dashboard. COUNTIF/MINIFS/MAXIFS formulas linked to Product Manager. Refreshes on file open or Ctrl+Alt+F9.
A5: Ball Valves, Gate Valves, etc. | B5: Print-ready price sheets. Every cell is a formula pointing to Product Manager. Grouped by product description and MOC.
A7: HOW LINKING WORKS
A8: Formula Example | B8: Cell K8 in Product Manager holds ₹5,755. Ball Valves sheet cell shows =\'📋 Product Manager\'!K8 — it always reads K8.
A9: Adding a product | B9: Add a row in Product Manager. Then go to the relevant type sheet and add a new formula row pointing to the new PM row. (Type sheets have fixed row refs, not dynamic lookup.)
A10: Price edit | B10: Edit column K (Rate_INR) in Product Manager. All linked type sheets update immediately.
A11: Status edit | B11: Edit column L (Status) to "Inactive". The value shows on type sheets. Filter by Status="Active" for website use.
A13: FOR WEBSITE / APP USE
A14: JSON Export | B14: The website should read 📋 Product Manager sheet directly (columns A–N, rows 8 onward). Filter out Status="Inactive" rows. Rate column is numeric for priced items, text "On Request" otherwise.
A15: Column Map | B15: A=Valve_Type, B=Valve_Name, C=Description, D=MOC, E=Size, F=Pressure_Class, G=End_Connection, H=Design_Standard, I=Hydro_Test, J=Unit, K=Rate_INR, L=Status, N=Remarks
A17: COLOR LEGEND
A18: Gold background | B18: Priced item (numeric Rate)
A19: Purple/mauve | B19: "On Request" item
A20: Green | B20: Active status
A21: Red | B21: Inactive status
A22: Dark navy row | B22: Product group header (pulled from PM)
A23: Steel blue row | B23: MOC sub-group header (pulled from PM)

Sheet Gate Valves
A1: SUNFORD VALVES COMPANY · GATE VALVES · PRICE LIST
A2: ⚡ LIVE — All data below is formula-linked to 📋 Product Manager. Edit prices there, they update here automatically.
A4: Sr. | B4: Product Description | C4: MOC / Material | D4: Size | E4: Pressure Class | F4: End Connection | G4: Design Standard | H4: Hydro Test | I4: Unit | J4: Rate (INR) | K4: Status | L4: Remarks
A5: ='📋 Product Manager'!B8
A6: =IFERROR(" Design: "&'📋 Product Manager'!H8&" · Hydro: "&'📋 Product Manager'!I8&" Kg/Cm²", "")
A7: =IFERROR(" MOC: "&'📋 Product Manager'!D8, "")
A8: 1 | B8: ='📋 Product Manager'!B8 | C8: ='📋 Product Manager'!D8 | D8: ='📋 Product Manager'!E8 | E8: =IFERROR(IF('📋 Product Manager'!F8<>"",'📋 Product Manager'!F8,'📋 Product Manager'!G8),"") | F8: ='📋 Product Manager'!G8 | G8: ='📋 Product Manager'!H8 | H8: ='📋 Product Manager'!I8 | I8: ='📋 Product Manager'!J8 | J8: ='📋 Product Manager'!K8 | K8: ='📋 Product Manager'!L8 | L8: =IFERROR(IF('📋 Product Manager'!N8="","",'📋 Product Manager'!N8),"")
A9: 2 | B9: ='📋 Product Manager'!B9 | C9: ='📋 Product Manager'!D9 | D9: ='📋 Product Manager'!E9 | E9: =IFERROR(IF('📋 Product Manager'!F9<>"",'📋 Product Manager'!F9,'📋 Product Manager'!G9),"") | F9: ='📋 Product Manager'!G9 | G9: ='📋 Product Manager'!H9 | H9: ='📋 Product Manager'!I9 | I9: ='📋 Product Manager'!J9 | J9: ='📋 Product Manager'!K9 | K9: ='📋 Product Manager'!L9 | L9: =IFERROR(IF('📋 Product Manager'!N9="","",'📋 Product Manager'!N9),"")
A10: 3 | B10: ='📋 Product Manager'!B10 | C10: ='📋 Product Manager'!D10 | D10: ='📋 Product Manager'!E10 | E10: =IFERROR(IF('📋 Product Manager'!F10<>"",'📋 Product Manager'!F10,'📋 Product Manager'!G10),"") | F10: ='📋 Product Manager'!G10 | G10: ='📋 Product Manager'!H10 | H10: ='📋 Product Manager'!I10 | I10: ='📋 Product Manager'!J10 | J10: ='📋 Product Manager'!K10 | K10: ='📋 Product Manager'!L10 | L10: =IFERROR(IF('📋 Product Manager'!N10="","",'📋 Product Manager'!N10),"")
A11: 4 | B11: ='📋 Product Manager'!B11 | C11: ='📋 Product Manager'!D11 | D11: ='📋 Product Manager'!E11 | E11: =IFERROR(IF('📋 Product Manager'!F11<>"",'📋 Product Manager'!F11,'📋 Product Manager'!G11),"") | F11: ='📋 Product Manager'!G11 | G11: ='📋 Product Manager'!H11 | H11: ='📋 Product Manager'!I11 | I11: ='📋 Product Manager'!J11 | J11: ='📋 Product Manager'!K11 | K11: ='📋 Product Manager'!L11 | L11: =IFERROR(IF('📋 Product Manager'!N11="","",'📋 Product Manager'!N11),"")
A12: 5 | B12: ='📋 Product Manager'!B12 | C12: ='📋 Product Manager'!D12 | D12: ='📋 Product Manager'!E12 | E12: =IFERROR(IF('📋 Product Manager'!F12<>"",'📋 Product Manager'!F12,'📋 Product Manager'!G12),"") | F12: ='📋 Product Manager'!G12 | G12: ='📋 Product Manager'!H12 | H12: ='📋 Product Manager'!I12 | I12: ='📋 Product Manager'!J12 | J12: ='📋 Product Manager'!K12 | K12: ='📋 Product Manager'!L12 | L12: =IFERROR(IF('📋 Product Manager'!N12="","",'📋 Product Manager'!N12),"")
A13: 6 | B13: ='📋 Product Manager'!B13 | C13: ='📋 Product Manager'!D13 | D13: ='📋 Product Manager'!E13 | E13: =IFERROR(IF('📋 Product Manager'!F13<>"",'📋 Product Manager'!F13,'📋 Product Manager'!G13),"") | F13: ='📋 Product Manager'!G13 | G13: ='📋 Product Manager'!H13 | H13: ='📋 Product Manager'!I13 | I13: ='📋 Product Manager'!J13 | J13: ='📋 Product Manager'!K13 | K13: ='📋 Product Manager'!L13 | L13: =IFERROR(IF('📋 Product Manager'!N13="","",'📋 Product Manager'!N13),"")
A14: 7 | B14: ='📋 Product Manager'!B14 | C14: ='📋 Product Manager'!D14 | D14: ='📋 Product Manager'!E14 | E14: =IFERROR(IF('📋 Product Manager'!F14<>"",'📋 Product Manager'!F14,'📋 Product Manager'!G14),"") | F14: ='📋 Product Manager'!G14 | G14: ='📋 Product Manager'!H14 | H14: ='📋 Product Manager'!I14 | I14: ='📋 Product Manager'!J14 | J14: ='📋 Product Manager'!K14 | K14: ='📋 Product Manager'!L14 | L14: =IFERROR(IF('📋 Product Manager'!N14="","",'📋 Product Manager'!N14),"")
A15: 8 | B15: ='📋 Product Manager'!B15 | C15: ='📋 Product Manager'!D15 | D15: ='📋 Product Manager'!E15 | E15: =IFERROR(IF('📋 Product Manager'!F15<>"",'📋 Product Manager'!F15,'📋 Product Manager'!G15),"") | F15: ='📋 Product Manager'!G15 | G15: ='📋 Product Manager'!H15 | H15: ='📋 Product Manager'!I15 | I15: ='📋 Product Manager'!J15 | J15: ='📋 Product Manager'!K15 | K15: ='📋 Product Manager'!L15 | L15: =IFERROR(IF('📋 Product Manager'!N15="","",'📋 Product Manager'!N15),"")
A16: 9 | B16: ='📋 Product Manager'!B16 | C16: ='📋 Product Manager'!D16 | D16: ='📋 Product Manager'!E16 | E16: =IFERROR(IF('📋 Product Manager'!F16<>"",'📋 Product Manager'!F16,'📋 Product Manager'!G16),"") | F16: ='📋 Product Manager'!G16 | G16: ='📋 Product Manager'!H16 | H16: ='📋 Product Manager'!I16 | I16: ='📋 Product Manager'!J16 | J16: ='📋 Product Manager'!K16 | K16: ='📋 Product Manager'!L16 | L16: =IFERROR(IF('📋 Product Manager'!N16="","",'📋 Product Manager'!N16),"")
A17: 10 | B17: ='📋 Product Manager'!B17 | C17: ='📋 Product Manager'!D17 | D17: ='📋 Product Manager'!E17 | E17: =IFERROR(IF('📋 Product Manager'!F17<>"",'📋 Product Manager'!F17,'📋 Product Manager'!G17),"") | F17: ='📋 Product Manager'!G17 | G17: ='📋 Product Manager'!H17 | H17: ='📋 Product Manager'!I17 | I17: ='📋 Product Manager'!J17 | J17: ='📋 Product Manager'!K17 | K17: ='📋 Product Manager'!L17 | L17: =IFERROR(IF('📋 Product Manager'!N17="","",'📋 Product Manager'!N17),"")
A18: 11 | B18: ='📋 Product Manager'!B18 | C18: ='📋 Product Manager'!D18 | D18: ='📋 Product Manager'!E18 | E18: =IFERROR(IF('📋 Product Manager'!F18<>"",'📋 Product Manager'!F18,'📋 Product Manager'!G18),"") | F18: ='📋 Product Manager'!G18 | G18: ='📋 Product Manager'!H18 | H18: ='📋 Product Manager'!I18 | I18: ='📋 Product Manager'!J18 | J18: ='📋 Product Manager'!K18 | K18: ='📋 Product Manager'!L18 | L18: =IFERROR(IF('📋 Product Manager'!N18="","",'📋 Product Manager'!N18),"")
A19: ='📋 Product Manager'!B37
A20: =IFERROR(" Design: "&'📋 Product Manager'!H37&" · Hydro: "&'📋 Product Manager'!I37&" Kg/Cm²", "")
A21: =IFERROR(" MOC: "&'📋 Product Manager'!D37, "")
A22: 12 | B22: ='📋 Product Manager'!B37 | C22: ='📋 Product Manager'!D37 | D22: ='📋 Product Manager'!E37 | E22: =IFERROR(IF('📋 Product Manager'!F37<>"",'📋 Product Manager'!F37,'📋 Product Manager'!G37),"") | F22: ='📋 Product Manager'!G37 | G22: ='📋 Product Manager'!H37 | H22: ='📋 Product Manager'!I37 | I22: ='📋 Product Manager'!J37 | J22: ='📋 Product Manager'!K37 | K22: ='📋 Product Manager'!L37 | L22: =IFERROR(IF('📋 Product Manager'!N37="","",'📋 Product Manager'!N37),"")
A23: 13 | B23: ='📋 Product Manager'!B38 | C23: ='📋 Product Manager'!D38 | D23: ='📋 Product Manager'!E38 | E23: =IFERROR(IF('📋 Product Manager'!F38<>"",'📋 Product Manager'!F38,'📋 Product Manager'!G38),"") | F23: ='📋 Product Manager'!G38 | G23: ='📋 Product Manager'!H38 | H23: ='📋 Product Manager'!I38 | I23: ='📋 Product Manager'!J38 | J23: ='📋 Product Manager'!K38 | K23: ='📋 Product Manager'!L38 | L23: =IFERROR(IF('📋 Product Manager'!N38="","",'📋 Product Manager'!N38),"")
A24: 14 | B24: ='📋 Product Manager'!B39 | C24: ='📋 Product Manager'!D39 | D24: ='📋 Product Manager'!E39 | E24: =IFERROR(IF('📋 Product Manager'!F39<>"",'📋 Product Manager'!F39,'📋 Product Manager'!G39),"") | F24: ='📋 Product Manager'!G39 | G24: ='📋 Product Manager'!H39 | H24: ='📋 Product Manager'!I39 | I24: ='📋 Product Manager'!J39 | J24: ='📋 Product Manager'!K39 | K24: ='📋 Product Manager'!L39 | L24: =IFERROR(IF('📋 Product Manager'!N39="","",'📋 Product Manager'!N39),"")
A25: 15 | B25: ='📋 Product Manager'!B40 | C25: ='📋 Product Manager'!D40 | D25: ='📋 Product Manager'!E40 | E25: =IFERROR(IF('📋 Product Manager'!F40<>"",'📋 Product Manager'!F40,'📋 Product Manager'!G40),"") | F25: ='📋 Product Manager'!G40 | G25: ='📋 Product Manager'!H40 | H25: ='📋 Product Manager'!I40 | I25: ='📋 Product Manager'!J40 | J25: ='📋 Product Manager'!K40 | K25: ='📋 Product Manager'!L40 | L25: =IFERROR(IF('📋 Product Manager'!N40="","",'📋 Product Manager'!N40),"")
A26: 16 | B26: ='📋 Product Manager'!B41 | C26: ='📋 Product Manager'!D41 | D26: ='📋 Product Manager'!E41 | E26: =IFERROR(IF('📋 Product Manager'!F41<>"",'📋 Product Manager'!F41,'📋 Product Manager'!G41),"") | F26: ='📋 Product Manager'!G41 | G26: ='📋 Product Manager'!H41 | H26: ='📋 Product Manager'!I41 | I26: ='📋 Product Manager'!J41 | J26: ='📋 Product Manager'!K41 | K26: ='📋 Product Manager'!L41 | L26: =IFERROR(IF('📋 Product Manager'!N41="","",'📋 Product Manager'!N41),"")
A28: ← Back to Product Manager | E28: ← Price Summary

Sheet Globe Valves
A1: SUNFORD VALVES COMPANY · GLOBE VALVES · PRICE LIST
A2: ⚡ LIVE — All data below is formula-linked to 📋 Product Manager. Edit prices there, they update here automatically.
A4: Sr. | B4: Product Description | C4: MOC / Material | D4: Size | E4: Pressure Class | F4: End Connection | G4: Design Standard | H4: Hydro Test | I4: Unit | J4: Rate (INR) | K4: Status | L4: Remarks
A5: ='📋 Product Manager'!B19
A6: =IFERROR(" Design: "&'📋 Product Manager'!H19&" · Hydro: "&'📋 Product Manager'!I19&" Kg/Cm²", "")
A7: =IFERROR(" MOC: "&'📋 Product Manager'!D19, "")
A8: 1 | B8: ='📋 Product Manager'!B19 | C8: ='📋 Product Manager'!D19 | D8: ='📋 Product Manager'!E19 | E8: =IFERROR(IF('📋 Product Manager'!F19<>"",'📋 Product Manager'!F19,'📋 Product Manager'!G19),"") | F8: ='📋 Product Manager'!G19 | G8: ='📋 Product Manager'!H19 | H8: ='📋 Product Manager'!I19 | I8: ='📋 Product Manager'!J19 | J8: ='📋 Product Manager'!K19 | K8: ='📋 Product Manager'!L19 | L8: =IFERROR(IF('📋 Product Manager'!N19="","",'📋 Product Manager'!N19),"")
A9: 2 | B9: ='📋 Product Manager'!B20 | C9: ='📋 Product Manager'!D20 | D9: ='📋 Product Manager'!E20 | E9: =IFERROR(IF('📋 Product Manager'!F20<>"",'📋 Product Manager'!F20,'📋 Product Manager'!G20),"") | F9: ='📋 Product Manager'!G20 | G9: ='📋 Product Manager'!H20 | H9: ='📋 Product Manager'!I20 | I9: ='📋 Product Manager'!J20 | J9: ='📋 Product Manager'!K20 | K9: ='📋 Product Manager'!L20 | L9: =IFERROR(IF('📋 Product Manager'!N20="","",'📋 Product Manager'!N20),"")
A10: 3 | B10: ='📋 Product Manager'!B21 | C10: ='📋 Product Manager'!D21 | D10: ='📋 Product Manager'!E21 | E10: =IFERROR(IF('📋 Product Manager'!F21<>"",'📋 Product Manager'!F21,'📋 Product Manager'!G21),"") | F10: ='📋 Product Manager'!G21 | G10: ='📋 Product Manager'!H21 | H10: ='📋 Product Manager'!I21 | I10: ='📋 Product Manager'!J21 | J10: ='📋 Product Manager'!K21 | K10: ='📋 Product Manager'!L21 | L10: =IFERROR(IF('📋 Product Manager'!N21="","",'📋 Product Manager'!N21),"")
A11: 4 | B11: ='📋 Product Manager'!B22 | C11: ='📋 Product Manager'!D22 | D11: ='📋 Product Manager'!E22 | E11: =IFERROR(IF('📋 Product Manager'!F22<>"",'📋 Product Manager'!F22,'📋 Product Manager'!G22),"") | F11: ='📋 Product Manager'!G22 | G11: ='📋 Product Manager'!H22 | H11: ='📋 Product Manager'!I22 | I11: ='📋 Product Manager'!J22 | J11: ='📋 Product Manager'!K22 | K11: ='📋 Product Manager'!L22 | L11: =IFERROR(IF('📋 Product Manager'!N22="","",'📋 Product Manager'!N22),"")
A12: 5 | B12: ='📋 Product Manager'!B23 | C12: ='📋 Product Manager'!D23 | D12: ='📋 Product Manager'!E23 | E12: =IFERROR(IF('📋 Product Manager'!F23<>"",'📋 Product Manager'!F23,'📋 Product Manager'!G23),"") | F12: ='📋 Product Manager'!G23 | G12: ='📋 Product Manager'!H23 | H12: ='📋 Product Manager'!I23 | I12: ='📋 Product Manager'!J23 | J12: ='📋 Product Manager'!K23 | K12: ='📋 Product Manager'!L23 | L12: =IFERROR(IF('📋 Product Manager'!N23="","",'📋 Product Manager'!N23),"")
A13: 6 | B13: ='📋 Product Manager'!B24 | C13: ='📋 Product Manager'!D24 | D13: ='📋 Product Manager'!E24 | E13: =IFERROR(IF('📋 Product Manager'!F24<>"",'📋 Product Manager'!F24,'📋 Product Manager'!G24),"") | F13: ='📋 Product Manager'!G24 | G13: ='📋 Product Manager'!H24 | H13: ='📋 Product Manager'!I24 | I13: ='📋 Product Manager'!J24 | J13: ='📋 Product Manager'!K24 | K13: ='📋 Product Manager'!L24 | L13: =IFERROR(IF('📋 Product Manager'!N24="","",'📋 Product Manager'!N24),"")
A14: 7 | B14: ='📋 Product Manager'!B25 | C14: ='📋 Product Manager'!D25 | D14: ='📋 Product Manager'!E25 | E14: =IFERROR(IF('📋 Product Manager'!F25<>"",'📋 Product Manager'!F25,'📋 Product Manager'!G25),"") | F14: ='📋 Product Manager'!G25 | G14: ='📋 Product Manager'!H25 | H14: ='📋 Product Manager'!I25 | I14: ='📋 Product Manager'!J25 | J14: ='📋 Product Manager'!K25 | K14: ='📋 Product Manager'!L25 | L14: =IFERROR(IF('📋 Product Manager'!N25="","",'📋 Product Manager'!N25),"")
A15: 8 | B15: ='📋 Product Manager'!B26 | C15: ='📋 Product Manager'!D26 | D15: ='📋 Product Manager'!E26 | E15: =IFERROR(IF('📋 Product Manager'!F26<>"",'📋 Product Manager'!F26,'📋 Product Manager'!G26),"") | F15: ='📋 Product Manager'!G26 | G15: ='📋 Product Manager'!H26 | H15: ='📋 Product Manager'!I26 | I15: ='📋 Product Manager'!J26 | J15: ='📋 Product Manager'!K26 | K15: ='📋 Product Manager'!L26 | L15: =IFERROR(IF('📋 Product Manager'!N26="","",'📋 Product Manager'!N26),"")
A16: 9 | B16: ='📋 Product Manager'!B27 | C16: ='📋 Product Manager'!D27 | D16: ='📋 Product Manager'!E27 | E16: =IFERROR(IF('📋 Product Manager'!F27<>"",'📋 Product Manager'!F27,'📋 Product Manager'!G27),"") | F16: ='📋 Product Manager'!G27 | G16: ='📋 Product Manager'!H27 | H16: ='📋 Product Manager'!I27 | I16: ='📋 Product Manager'!J27 | J16: ='📋 Product Manager'!K27 | K16: ='📋 Product Manager'!L27 | L16: =IFERROR(IF('📋 Product Manager'!N27="","",'📋 Product Manager'!N27),"")
A17: 10 | B17: ='📋 Product Manager'!B28 | C17: ='📋 Product Manager'!D28 | D17: ='📋 Product Manager'!E28 | E17: =IFERROR(IF('📋 Product Manager'!F28<>"",'📋 Product Manager'!F28,'📋 Product Manager'!G28),"") | F17: ='📋 Product Manager'!G28 | G17: ='📋 Product Manager'!H28 | H17: ='📋 Product Manager'!I28 | I17: ='📋 Product Manager'!J28 | J17: ='📋 Product Manager'!K28 | K17: ='📋 Product Manager'!L28 | L17: =IFERROR(IF('📋 Product Manager'!N28="","",'📋 Product Manager'!N28),"")
A19: ← Back to Product Manager | E19: ← Price Summary

Sheet Control Valves
A1: SUNFORD VALVES COMPANY · CONTROL VALVES · PRICE LIST
A2: ⚡ LIVE — All data below is formula-linked to 📋 Product Manager. Edit prices there, they update here automatically.
A4: Sr. | B4: Product Description | C4: MOC / Material | D4: Size | E4: Pressure Class | F4: End Connection | G4: Design Standard | H4: Hydro Test | I4: Unit | J4: Rate (INR) | K4: Status | L4: Remarks
A5: ='📋 Product Manager'!B29
A6: =IFERROR(" Design: "&'📋 Product Manager'!H29&" · Hydro: "&'📋 Product Manager'!I29&" Kg/Cm²", "")
A7: =IFERROR(" MOC: "&'📋 Product Manager'!D29, "")
A8: 1 | B8: ='📋 Product Manager'!B29 | C8: ='📋 Product Manager'!D29 | D8: ='📋 Product Manager'!E29 | E8: =IFERROR(IF('📋 Product Manager'!F29<>"",'📋 Product Manager'!F29,'📋 Product Manager'!G29),"") | F8: ='📋 Product Manager'!G29 | G8: ='📋 Product Manager'!H29 | H8: ='📋 Product Manager'!I29 | I8: ='📋 Product Manager'!J29 | J8: ='📋 Product Manager'!K29 | K8: ='📋 Product Manager'!L29 | L8: =IFERROR(IF('📋 Product Manager'!N29="","",'📋 Product Manager'!N29),"")
A9: 2 | B9: ='📋 Product Manager'!B30 | C9: ='📋 Product Manager'!D30 | D9: ='📋 Product Manager'!E30 | E9: =IFERROR(IF('📋 Product Manager'!F30<>"",'📋 Product Manager'!F30,'📋 Product Manager'!G30),"") | F9: ='📋 Product Manager'!G30 | G9: ='📋 Product Manager'!H30 | H9: ='📋 Product Manager'!I30 | I9: ='📋 Product Manager'!J30 | J9: ='📋 Product Manager'!K30 | K9: ='📋 Product Manager'!L30 | L9: =IFERROR(IF('📋 Product Manager'!N30="","",'📋 Product Manager'!N30),"")
A10: 3 | B10: ='📋 Product Manager'!B31 | C10: ='📋 Product Manager'!D31 | D10: ='📋 Product Manager'!E31 | E10: =IFERROR(IF('📋 Product Manager'!F31<>"",'📋 Product Manager'!F31,'📋 Product Manager'!G31),"") | F10: ='📋 Product Manager'!G31 | G10: ='📋 Product Manager'!H31 | H10: ='📋 Product Manager'!I31 | I10: ='📋 Product Manager'!J31 | J10: ='📋 Product Manager'!K31 | K10: ='📋 Product Manager'!L31 | L10: =IFERROR(IF('📋 Product Manager'!N31="","",'📋 Product Manager'!N31),"")
A11: 4 | B11: ='📋 Product Manager'!B32 | C11: ='📋 Product Manager'!D32 | D11: ='📋 Product Manager'!E32 | E11: =IFERROR(IF('📋 Product Manager'!F32<>"",'📋 Product Manager'!F32,'📋 Product Manager'!G32),"") | F11: ='📋 Product Manager'!G32 | G11: ='📋 Product Manager'!H32 | H11: ='📋 Product Manager'!I32 | I11: ='📋 Product Manager'!J32 | J11: ='📋 Product Manager'!K32 | K11: ='📋 Product Manager'!L32 | L11: =IFERROR(IF('📋 Product Manager'!N32="","",'📋 Product Manager'!N32),"")
A12: 5 | B12: ='📋 Product Manager'!B33 | C12: ='📋 Product Manager'!D33 | D12: ='📋 Product Manager'!E33 | E12: =IFERROR(IF('📋 Product Manager'!F33<>"",'📋 Product Manager'!F33,'📋 Product Manager'!G33),"") | F12: ='📋 Product Manager'!G33 | G12: ='📋 Product Manager'!H33 | H12: ='📋 Product Manager'!I33 | I12: ='📋 Product Manager'!J33 | J12: ='📋 Product Manager'!K33 | K12: ='📋 Product Manager'!L33 | L12: =IFERROR(IF('📋 Product Manager'!N33="","",'📋 Product Manager'!N33),"")
A13: 6 | B13: ='📋 Product Manager'!B34 | C13: ='📋 Product Manager'!D34 | D13: ='📋 Product Manager'!E34 | E13: =IFERROR(IF('📋 Product Manager'!F34<>"",'📋 Product Manager'!F34,'📋 Product Manager'!G34),"") | F13: ='📋 Product Manager'!G34 | G13: ='📋 Product Manager'!H34 | H13: ='📋 Product Manager'!I34 | I13: ='📋 Product Manager'!J34 | J13: ='📋 Product Manager'!K34 | K13: ='📋 Product Manager'!L34 | L13: =IFERROR(IF('📋 Product Manager'!N34="","",'📋 Product Manager'!N34),"")
A14: 7 | B14: ='📋 Product Manager'!B35 | C14: ='📋 Product Manager'!D35 | D14: ='📋 Product Manager'!E35 | E14: =IFERROR(IF('📋 Product Manager'!F35<>"",'📋 Product Manager'!F35,'📋 Product Manager'!G35),"") | F14: ='📋 Product Manager'!G35 | G14: ='📋 Product Manager'!H35 | H14: ='📋 Product Manager'!I35 | I14: ='📋 Product Manager'!J35 | J14: ='📋 Product Manager'!K35 | K14: ='📋 Product Manager'!L35 | L14: =IFERROR(IF('📋 Product Manager'!N35="","",'📋 Product Manager'!N35),"")
A15: 8 | B15: ='📋 Product Manager'!B36 | C15: ='📋 Product Manager'!D36 | D15: ='📋 Product Manager'!E36 | E15: =IFERROR(IF('📋 Product Manager'!F36<>"",'📋 Product Manager'!F36,'📋 Product Manager'!G36),"") | F15: ='📋 Product Manager'!G36 | G15: ='📋 Product Manager'!H36 | H15: ='📋 Product Manager'!I36 | I15: ='📋 Product Manager'!J36 | J15: ='📋 Product Manager'!K36 | K15: ='📋 Product Manager'!L36 | L15: =IFERROR(IF('📋 Product Manager'!N36="","",'📋 Product Manager'!N36),"")
A16: ='📋 Product Manager'!B146
A17: =IFERROR(" Design: "&'📋 Product Manager'!H146&" · Hydro: "&'📋 Product Manager'!I146&" Kg/Cm²", "")
A18: =IFERROR(" MOC: "&'📋 Product Manager'!D146, "")
A19: 9 | B19: ='📋 Product Manager'!B146 | C19: ='📋 Product Manager'!D146 | D19: ='📋 Product Manager'!E146 | E19: =IFERROR(IF('📋 Product Manager'!F146<>"",'📋 Product Manager'!F146,'📋 Product Manager'!G146),"") | F19: ='📋 Product Manager'!G146 | G19: ='📋 Product Manager'!H146 | H19: ='📋 Product Manager'!I146 | I19: ='📋 Product Manager'!J146 | J19: ='📋 Product Manager'!K146 | K19: ='📋 Product Manager'!L146 | L19: =IFERROR(IF('📋 Product Manager'!N146="","",'📋 Product Manager'!N146),"")
A20: 10 | B20: ='📋 Product Manager'!B147 | C20: ='📋 Product Manager'!D147 | D20: ='📋 Product Manager'!E147 | E20: =IFERROR(IF('📋 Product Manager'!F147<>"",'📋 Product Manager'!F147,'📋 Product Manager'!G147),"") | F20: ='📋 Product Manager'!G147 | G20: ='📋 Product Manager'!H147 | H20: ='📋 Product Manager'!I147 | I20: ='📋 Product Manager'!J147 | J20: ='📋 Product Manager'!K147 | K20: ='📋 Product Manager'!L147 | L20: =IFERROR(IF('📋 Product Manager'!N147="","",'📋 Product Manager'!N147),"")
A21: 11 | B21: ='📋 Product Manager'!B148 | C21: ='📋 Product Manager'!D148 | D21: ='📋 Product Manager'!E148 | E21: =IFERROR(IF('📋 Product Manager'!F148<>"",'📋 Product Manager'!F148,'📋 Product Manager'!G148),"") | F21: ='📋 Product Manager'!G148 | G21: ='📋 Product Manager'!H148 | H21: ='📋 Product Manager'!I148 | I21: ='📋 Product Manager'!J148 | J21: ='📋 Product Manager'!K148 | K21: ='📋 Product Manager'!L148 | L21: =IFERROR(IF('📋 Product Manager'!N148="","",'📋 Product Manager'!N148),"")
A22: 12 | B22: ='📋 Product Manager'!B149 | C22: ='📋 Product Manager'!D149 | D22: ='📋 Product Manager'!E149 | E22: =IFERROR(IF('📋 Product Manager'!F149<>"",'📋 Product Manager'!F149,'📋 Product Manager'!G149),"") | F22: ='📋 Product Manager'!G149 | G22: ='📋 Product Manager'!H149 | H22: ='📋 Product Manager'!I149 | I22: ='📋 Product Manager'!J149 | J22: ='📋 Product Manager'!K149 | K22: ='📋 Product Manager'!L149 | L22: =IFERROR(IF('📋 Product Manager'!N149="","",'📋 Product Manager'!N149),"")
A23: 13 | B23: ='📋 Product Manager'!B150 | C23: ='📋 Product Manager'!D150 | D23: ='📋 Product Manager'!E150 | E23: =IFERROR(IF('📋 Product Manager'!F150<>"",'📋 Product Manager'!F150,'📋 Product Manager'!G150),"") | F23: ='📋 Product Manager'!G150 | G23: ='📋 Product Manager'!H150 | H23: ='📋 Product Manager'!I150 | I23: ='📋 Product Manager'!J150 | J23: ='📋 Product Manager'!K150 | K23: ='📋 Product Manager'!L150 | L23: =IFERROR(IF('📋 Product Manager'!N150="","",'📋 Product Manager'!N150),"")
A24: ='📋 Product Manager'!B151
A25: =IFERROR(" Design: "&'📋 Product Manager'!H151&" · Hydro: "&'📋 Product Manager'!I151&" Kg/Cm²", "")
A26: =IFERROR(" MOC: "&'📋 Product Manager'!D151, "")
A27: 14 | B27: ='📋 Product Manager'!B151 | C27: ='📋 Product Manager'!D151 | D27: ='📋 Product Manager'!E151 | E27: =IFERROR(IF('📋 Product Manager'!F151<>"",'📋 Product Manager'!F151,'📋 Product Manager'!G151),"") | F27: ='📋 Product Manager'!G151 | G27: ='📋 Product Manager'!H151 | H27: ='📋 Product Manager'!I151 | I27: ='📋 Product Manager'!J151 | J27: ='📋 Product Manager'!K151 | K27: ='📋 Product Manager'!L151 | L27: =IFERROR(IF('📋 Product Manager'!N151="","",'📋 Product Manager'!N151),"")
A28: 15 | B28: ='📋 Product Manager'!B152 | C28: ='📋 Product Manager'!D152 | D28: ='📋 Product Manager'!E152 | E28: =IFERROR(IF('📋 Product Manager'!F152<>"",'📋 Product Manager'!F152,'📋 Product Manager'!G152),"") | F28: ='📋 Product Manager'!G152 | G28: ='📋 Product Manager'!H152 | H28: ='📋 Product Manager'!I152 | I28: ='📋 Product Manager'!J152 | J28: ='📋 Product Manager'!K152 | K28: ='📋 Product Manager'!L152 | L28: =IFERROR(IF('📋 Product Manager'!N152="","",'📋 Product Manager'!N152),"")
A29: 16 | B29: ='📋 Product Manager'!B153 | C29: ='📋 Product Manager'!D153 | D29: ='📋 Product Manager'!E153 | E29: =IFERROR(IF('📋 Product Manager'!F153<>"",'📋 Product Manager'!F153,'📋 Product Manager'!G153),"") | F29: ='📋 Product Manager'!G153 | G29: ='📋 Product Manager'!H153 | H29: ='📋 Product Manager'!I153 | I29: ='📋 Product Manager'!J153 | J29: ='📋 Product Manager'!K153 | K29: ='📋 Product Manager'!L153 | L29: =IFERROR(IF('📋 Product Manager'!N153="","",'📋 Product Manager'!N153),"")
A30: ='📋 Product Manager'!B154
A31: =IFERROR(" Design: "&'📋 Product Manager'!H154&" · Hydro: "&'📋 Product Manager'!I154&" Kg/Cm²", "")
A32: =IFERROR(" MOC: "&'📋 Product Manager'!D154, "")
A33: 17 | B33: ='📋 Product Manager'!B154 | C33: ='📋 Product Manager'!D154 | D33: ='📋 Product Manager'!E154 | E33: =IFERROR(IF('📋 Product Manager'!F154<>"",'📋 Product Manager'!F154,'📋 Product Manager'!G154),"") | F33: ='📋 Product Manager'!G154 | G33: ='📋 Product Manager'!H154 | H33: ='📋 Product Manager'!I154 | I33: ='📋 Product Manager'!J154 | J33: ='📋 Product Manager'!K154 | K33: ='📋 Product Manager'!L154 | L33: =IFERROR(IF('📋 Product Manager'!N154="","",'📋 Product Manager'!N154),"")
A34: 18 | B34: ='📋 Product Manager'!B155 | C34: ='📋 Product Manager'!D155 | D34: ='📋 Product Manager'!E155 | E34: =IFERROR(IF('📋 Product Manager'!F155<>"",'📋 Product Manager'!F155,'📋 Product Manager'!G155),"") | F34: ='📋 Product Manager'!G155 | G34: ='📋 Product Manager'!H155 | H34: ='📋 Product Manager'!I155 | I34: ='📋 Product Manager'!J155 | J34: ='📋 Product Manager'!K155 | K34: ='📋 Product Manager'!L155 | L34: =IFERROR(IF('📋 Product Manager'!N155="","",'📋 Product Manager'!N155),"")
A35: 19 | B35: ='📋 Product Manager'!B156 | C35: ='📋 Product Manager'!D156 | D35: ='📋 Product Manager'!E156 | E35: =IFERROR(IF('📋 Product Manager'!F156<>"",'📋 Product Manager'!F156,'📋 Product Manager'!G156),"") | F35: ='📋 Product Manager'!G156 | G35: ='📋 Product Manager'!H156 | H35: ='📋 Product Manager'!I156 | I35: ='📋 Product Manager'!J156 | J35: ='📋 Product Manager'!K156 | K35: ='📋 Product Manager'!L156 | L35: =IFERROR(IF('📋 Product Manager'!N156="","",'📋 Product Manager'!N156),"")
A36: 20 | B36: ='📋 Product Manager'!B157 | C36: ='📋 Product Manager'!D157 | D36: ='📋 Product Manager'!E157 | E36: =IFERROR(IF('📋 Product Manager'!F157<>"",'📋 Product Manager'!F157,'📋 Product Manager'!G157),"") | F36: ='📋 Product Manager'!G157 | G36: ='📋 Product Manager'!H157 | H36: ='📋 Product Manager'!I157 | I36: ='📋 Product Manager'!J157 | J36: ='📋 Product Manager'!K157 | K36: ='📋 Product Manager'!L157 | L36: =IFERROR(IF('📋 Product Manager'!N157="","",'📋 Product Manager'!N157),"")
A37: 21 | B37: ='📋 Product Manager'!B158 | C37: ='📋 Product Manager'!D158 | D37: ='📋 Product Manager'!E158 | E37: =IFERROR(IF('📋 Product Manager'!F158<>"",'📋 Product Manager'!F158,'📋 Product Manager'!G158),"") | F37: ='📋 Product Manager'!G158 | G37: ='📋 Product Manager'!H158 | H37: ='📋 Product Manager'!I158 | I37: ='📋 Product Manager'!J158 | J37: ='📋 Product Manager'!K158 | K37: ='📋 Product Manager'!L158 | L37: =IFERROR(IF('📋 Product Manager'!N158="","",'📋 Product Manager'!N158),"")
A38: ='📋 Product Manager'!B159
A39: =IFERROR(" Design: "&'📋 Product Manager'!H159&" · Hydro: "&'📋 Product Manager'!I159&" Kg/Cm²", "")
A40: =IFERROR(" MOC: "&'📋 Product Manager'!D159, "")
A41: 22 | B41: ='📋 Product Manager'!B159 | C41: ='📋 Product Manager'!D159 | D41: ='📋 Product Manager'!E159 | E41: =IFERROR(IF('📋 Product Manager'!F159<>"",'📋 Product Manager'!F159,'📋 Product Manager'!G159),"") | F41: ='📋 Product Manager'!G159 | G41: ='📋 Product Manager'!H159 | H41: ='📋 Product Manager'!I159 | I41: ='📋 Product Manager'!J159 | J41: ='📋 Product Manager'!K159 | K41: ='📋 Product Manager'!L159 | L41: =IFERROR(IF('📋 Product Manager'!N159="","",'📋 Product Manager'!N159),"")
...

Sheet Strainers
A1: SUNFORD VALVES COMPANY · STRAINERS · PRICE LIST
A2: ⚡ LIVE — All data below is formula-linked to 📋 Product Manager. Edit prices there, they update here automatically.
A4: Sr. | B4: Product Description | C4: MOC / Material | D4: Size | E4: Pressure Class | F4: End Connection | G4: Design Standard | H4: Hydro Test | I4: Unit | J4: Rate (INR) | K4: Status | L4: Remarks
A5: ='📋 Product Manager'!B42
A6: =IFERROR(" Design: "&'📋 Product Manager'!H42&" · Hydro: "&'📋 Product Manager'!I42&" Kg/Cm²", "")
A7: =IFERROR(" MOC: "&'📋 Product Manager'!D42, "")
A8: 1 | B8: ='📋 Product Manager'!B42 | C8: ='📋 Product Manager'!D42 | D8: ='📋 Product Manager'!E42 | E8: =IFERROR(IF('📋 Product Manager'!F42<>"",'📋 Product Manager'!F42,'📋 Product Manager'!G42),"") | F8: ='📋 Product Manager'!G42 | G8: ='📋 Product Manager'!H42 | H8: ='📋 Product Manager'!I42 | I8: ='📋 Product Manager'!J42 | J8: ='📋 Product Manager'!K42 | K8: ='📋 Product Manager'!L42 | L8: =IFERROR(IF('📋 Product Manager'!N42="","",'📋 Product Manager'!N42),"")
A9: 2 | B9: ='📋 Product Manager'!B43 | C9: ='📋 Product Manager'!D43 | D9: ='📋 Product Manager'!E43 | E9: =IFERROR(IF('📋 Product Manager'!F43<>"",'📋 Product Manager'!F43,'📋 Product Manager'!G43),"") | F9: ='📋 Product Manager'!G43 | G9: ='📋 Product Manager'!H43 | H9: ='📋 Product Manager'!I43 | I9: ='📋 Product Manager'!J43 | J9: ='📋 Product Manager'!K43 | K9: ='📋 Product Manager'!L43 | L9: =IFERROR(IF('📋 Product Manager'!N43="","",'📋 Product Manager'!N43),"")
A10: 3 | B10: ='📋 Product Manager'!B44 | C10: ='📋 Product Manager'!D44 | D10: ='📋 Product Manager'!E44 | E10: =IFERROR(IF('📋 Product Manager'!F44<>"",'📋 Product Manager'!F44,'📋 Product Manager'!G44),"") | F10: ='📋 Product Manager'!G44 | G10: ='📋 Product Manager'!H44 | H10: ='📋 Product Manager'!I44 | I10: ='📋 Product Manager'!J44 | J10: ='📋 Product Manager'!K44 | K10: ='📋 Product Manager'!L44 | L10: =IFERROR(IF('📋 Product Manager'!N44="","",'📋 Product Manager'!N44),"")
A11: 4 | B11: ='📋 Product Manager'!B45 | C11: ='📋 Product Manager'!D45 | D11: ='📋 Product Manager'!E45 | E11: =IFERROR(IF('📋 Product Manager'!F45<>"",'📋 Product Manager'!F45,'📋 Product Manager'!G45),"") | F11: ='📋 Product Manager'!G45 | G11: ='📋 Product Manager'!H45 | H11: ='📋 Product Manager'!I45 | I11: ='📋 Product Manager'!J45 | J11: ='📋 Product Manager'!K45 | K11: ='📋 Product Manager'!L45 | L11: =IFERROR(IF('📋 Product Manager'!N45="","",'📋 Product Manager'!N45),"")
A12: 5 | B12: ='📋 Product Manager'!B46 | C12: ='📋 Product Manager'!D46 | D12: ='📋 Product Manager'!E46 | E12: =IFERROR(IF('📋 Product Manager'!F46<>"",'📋 Product Manager'!F46,'📋 Product Manager'!G46),"") | F12: ='📋 Product Manager'!G46 | G12: ='📋 Product Manager'!H46 | H12: ='📋 Product Manager'!I46 | I12: ='📋 Product Manager'!J46 | J12: ='📋 Product Manager'!K46 | K12: ='📋 Product Manager'!L46 | L12: =IFERROR(IF('📋 Product Manager'!N46="","",'📋 Product Manager'!N46),"")
A13: 6 | B13: ='📋 Product Manager'!B47 | C13: ='📋 Product Manager'!D47 | D13: ='📋 Product Manager'!E47 | E13: =IFERROR(IF('📋 Product Manager'!F47<>"",'📋 Product Manager'!F47,'📋 Product Manager'!G47),"") | F13: ='📋 Product Manager'!G47 | G13: ='📋 Product Manager'!H47 | H13: ='📋 Product Manager'!I47 | I13: ='📋 Product Manager'!J47 | J13: ='📋 Product Manager'!K47 | K13: ='📋 Product Manager'!L47 | L13: =IFERROR(IF('📋 Product Manager'!N47="","",'📋 Product Manager'!N47),"")
A14: 7 | B14: ='📋 Product Manager'!B48 | C14: ='📋 Product Manager'!D48 | D14: ='📋 Product Manager'!E48 | E14: =IFERROR(IF('📋 Product Manager'!F48<>"",'📋 Product Manager'!F48,'📋 Product Manager'!G48),"") | F14: ='📋 Product Manager'!G48 | G14: ='📋 Product Manager'!H48 | H14: ='📋 Product Manager'!I48 | I14: ='📋 Product Manager'!J48 | J14: ='📋 Product Manager'!K48 | K14: ='📋 Product Manager'!L48 | L14: =IFERROR(IF('📋 Product Manager'!N48="","",'📋 Product Manager'!N48),"")
A15: 8 | B15: ='📋 Product Manager'!B49 | C15: ='📋 Product Manager'!D49 | D15: ='📋 Product Manager'!E49 | E15: =IFERROR(IF('📋 Product Manager'!F49<>"",'📋 Product Manager'!F49,'📋 Product Manager'!G49),"") | F15: ='📋 Product Manager'!G49 | G15: ='📋 Product Manager'!H49 | H15: ='📋 Product Manager'!I49 | I15: ='📋 Product Manager'!J49 | J15: ='📋 Product Manager'!K49 | K15: ='📋 Product Manager'!L49 | L15: =IFERROR(IF('📋 Product Manager'!N49="","",'📋 Product Manager'!N49),"")
A16: 9 | B16: ='📋 Product Manager'!B50 | C16: ='📋 Product Manager'!D50 | D16: ='📋 Product Manager'!E50 | E16: =IFERROR(IF('📋 Product Manager'!F50<>"",'📋 Product Manager'!F50,'📋 Product Manager'!G50),"") | F16: ='📋 Product Manager'!G50 | G16: ='📋 Product Manager'!H50 | H16: ='📋 Product Manager'!I50 | I16: ='📋 Product Manager'!J50 | J16: ='📋 Product Manager'!K50 | K16: ='📋 Product Manager'!L50 | L16: =IFERROR(IF('📋 Product Manager'!N50="","",'📋 Product Manager'!N50),"")
A17: 10 | B17: ='📋 Product Manager'!B51 | C17: ='📋 Product Manager'!D51 | D17: ='📋 Product Manager'!E51 | E17: =IFERROR(IF('📋 Product Manager'!F51<>"",'📋 Product Manager'!F51,'📋 Product Manager'!G51),"") | F17: ='📋 Product Manager'!G51 | G17: ='📋 Product Manager'!H51 | H17: ='📋 Product Manager'!I51 | I17: ='📋 Product Manager'!J51 | J17: ='📋 Product Manager'!K51 | K17: ='📋 Product Manager'!L51 | L17: =IFERROR(IF('📋 Product Manager'!N51="","",'📋 Product Manager'!N51),"")
A19: ← Back to Product Manager | E19: ← Price Summary

Sheet Check Valves
A1: SUNFORD VALVES COMPANY · CHECK VALVES · PRICE LIST
